Unhandled error processing page session lChZ0IPoataat12I: Traceback (most recent call last):
  File "C:\Users\sunny\AppData\Local\Programs\Python\Python313\Lib\site-packages\flet_web\fastapi\flet_app.py", line 141, in __on_session_created
    await asyncio.get_running_loop().run_in_executor(
        app_manager.executor, self.__session_handler, self.__page
    )
  File "C:\Users\sunny\AppData\Local\Programs\Python\Python313\Lib\concurrent\futures\thread.py", line 59, in run
    result = self.fn(*self.args, **self.kwargs)
  File "c:\Users\sunny\Downloads\import flet as ft.py", line 227, in main
    refresh_output()
    ~~~~~~~~~~~~~~^^
  File "c:\Users\sunny\Downloads\import flet as ft.py", line 135, in refresh_output
    details = f"🏟️ Venue: {event['venue']}\n📅 Date: {event['date']}\n⏰ Time: {event['time']}"
                           ~~~~~^^^^^^^^^
KeyError: 'venue'
